
try {
    foo;
}
catch(err) {
    console.log('***ERROR', err.message);
}